Workbook

Sheet Comparison
A1: Daura LGA, Katsina State: attendees vs non-attenders
A2: PRACTICE DATA (synthetic). Not real households or real programme results. All figures are live formulas on the Attendees, NonAttendees and Staff sheets.
A4: Attendees (records) | B4: =COUNTA(Attendees!$A$2:$A$31) -> 30
A5: Non-attenders (households) | B5: =COUNTA(NonAttendees!$A$2:$A$41) -> 40
A6: Staff (records) | B6: =COUNTA(Staff!$A$2:$A$4) -> 3
A8: Summary for the one-page version
A9: Each cell reads: count of base (percentage).
B10: Attendees (30) | D10: Non-attenders (40)
A11: Information problem | B11: =B29&" of "&$B$4&" ("&TEXT(B29/$B$4,"0%")&")" -> 7 of 30 (23%) | D11: =D29&" of "&$B$5&" ("&TEXT(D29/$B$5,"0%")&")" -> 17 of 40 (43%)
A12: Median distance to the outreach (km) | B12: =TEXT(B61,"0.0#") -> 2.3 | D12: =TEXT(D61,"0.0#") -> 3.65
A13: Median travel time (minutes) | B13: =TEXT(B65,"0") -> 33 | D13: =TEXT(D65,"0") -> 45
A14: Heard through a CHW or community leader | B14: =B82&" of "&$B$4&" ("&TEXT(B82/$B$4,"0%")&")" -> 15 of 30 (50%) | D14: =D82&" of "&$D$73&" ("&TEXT(D82/$D$73,"0%")&")"&" of those aware" -> 17 of 28 (61%) of those aware
A15: Distance or transport cost as the main barrier / reason | B15: =B37&" of "&$B$4&" ("&TEXT(B37/$B$4,"0%")&")" -> 4 of 30 (13%) | D15: =D37&" of "&$B$5&" ("&TEXT(D37/$B$5,"0%")&")" -> 6 of 40 (15%)
A16: Most common ask | B16: ="Shorter waiting time: "&B89&" of "&$B$88 -> Shorter waiting time: 10 of 29 | D16: ="Closer service point: "&D91&" of "&$B$5 -> Closer service point: 9 of 40
A17: Would use again / would attend next time (Yes) | B17: =B102&" of "&$B$4&" ("&TEXT(B102/$B$4,"0%")&")" -> 18 of 30 (60%) | D17: =D102&" of "&$B$5&" ("&TEXT(D102/$B$5,"0%")&")" -> 20 of 40 (50%)
A18: Waiting time as an issue | B18: ="Waited over 60 min: "&B120&" of "&B121 -> Waited over 60 min: 7 of 29 | D18: ="Gave long waits as the reason: "&D43&" of "&$B$5 -> Gave long waits as the reason: 2 of 40
A19: Where the information gap shows up | B19: =IF(B52/C52>D52/E52,"Kusugu: "&B52&" of "&C52,"Sarkin Yara: "&D52&" of "&E52) -> Kusugu: 5 of 15 | D19: =IF(B53/C53>D53/E53,"Kusugu: "&B53&" of "&C53&" never heard","Sarkin Yara: "&D53&" of "&E53&" never heard") -> Sarkin Yara: 8 of 20 never heard
A20: Never-heard households open to attending (Yes or Maybe) | B20: n/a | D20: =(B109+B110)&" of "&B108 -> 10 of 12
A24: 1. The information problem
A25: Attendees: main barrier before attending. Non-attenders: main reason for not attending.
B26: Attendees (n) | C26: % of 30 | D26: Non-attenders (n) | E26: % of 40
A27: Lack of information / did not know about it | B27: =COUNTIFS(Attendees!$M$2:$M$31,"Lack of information") -> 7 | C27: =IF(ISNUMBER(B27),B27/$B$4,"n/a") -> 0.23333333 | D27: =COUNTIFS(NonAttendees!$N$2:$N$41,"Did not know about it") -> 12 | E27: =D27/$B$5 -> 0.3
A28: Heard about it too late | B28: n/a | C28: =IF(ISNUMBER(B28),B28/$B$4,"n/a") -> n/a | D28: =COUNTIFS(NonAttendees!$N$2:$N$41,"Heard too late") -> 5 | E28: =D28/$B$5 -> 0.125
A29: Information-related, total | B29: =B27 -> 7 | C29: =B29/$B$4 -> 0.23333333 | D29: =D27+D28 -> 17 | E29: =D29/$B$5 -> 0.425
A32: 2. Barriers (attendees) and reasons (non-attenders), grouped
A33: Groups follow the mapping on the Notes sheet. "n/a" means the option did not exist for that group.
B34: Attendees (n) | C34: % of 30 | D34: Non-attenders (n) | E34: % of 40
A35: Lack of information / did not know | B35: =COUNTIFS(Attendees!$M$2:$M$31,"Lack of information") -> 7 | C35: =IF(ISNUMBER(B35),B35/$B$4,"n/a") -> 0.23333333 | D35: =COUNTIFS(NonAttendees!$N$2:$N$41,"Did not know about it") -> 12 | E35: =IF(ISNUMBER(D35),D35/$B$5,"n/a") -> 0.3
A36: Heard too late | B36: n/a | C36: =IF(ISNUMBER(B36),B36/$B$4,"n/a") -> n/a | D36: =COUNTIFS(NonAttendees!$N$2:$N$41,"Heard too late") -> 5 | E36: =IF(ISNUMBER(D36),D36/$B$5,"n/a") -> 0.125
A37: Distance / transport cost | B37: =COUNTIFS(Attendees!$M$2:$M$31,"Distance/transport cost") -> 4 | C37: =IF(ISNUMBER(B37),B37/$B$4,"n/a") -> 0.13333333 | D37: =COUNTIFS(NonAttendees!$N$2:$N$41,"Distance/transport cost") -> 6 | E37: =IF(ISNUMBER(D37),D37/$B$5,"n/a") -> 0.15
A38: Work / household responsibilities | B38: =COUNTIFS(Attendees!$M$2:$M$31,"Work/household responsibilities") -> 2 | C38: =IF(ISNUMBER(B38),B38/$B$4,"n/a") -> 0.066666667 | D38: =COUNTIFS(NonAttendees!$N$2:$N$41,"Work/household responsibilities") -> 5 | E38: =IF(ISNUMBER(D38),D38/$B$5,"n/a") -> 0.125
A39: Language / communication | B39: =COUNTIFS(Attendees!$M$2:$M$31,"Language/communication") -> 4 | C39: =IF(ISNUMBER(B39),B39/$B$4,"n/a") -> 0.13333333 | D39: =COUNTIFS(NonAttendees!$N$2:$N$41,"Language/communication") -> 2 | E39: =IF(ISNUMBER(D39),D39/$B$5,"n/a") -> 0.05
A40: Previous bad service experience | B40: =COUNTIFS(Attendees!$M$2:$M$31,"Previous bad service experience") -> 2 | C40: =IF(ISNUMBER(B40),B40/$B$4,"n/a") -> 0.066666667 | D40: =COUNTIFS(NonAttendees!$N$2:$N$41,"Previous bad service experience") -> 3 | E40: =IF(ISNUMBER(D40),D40/$B$5,"n/a") -> 0.075
A41: Cost of other related services | B41: =COUNTIFS(Attendees!$M$2:$M$31,"Cost of other related services") -> 1 | C41: =IF(ISNUMBER(B41),B41/$B$4,"n/a") -> 0.033333333 | D41: n/a | E41: =IF(ISNUMBER(D41),D41/$B$5,"n/a") -> n/a
A42: Concern about the service | B42: n/a | C42: =IF(ISNUMBER(B42),B42/$B$4,"n/a") -> n/a | D42: =COUNTIFS(NonAttendees!$N$2:$N$41,"Concern about the service") -> 3 | E42: =IF(ISNUMBER(D42),D42/$B$5,"n/a") -> 0.075
A43: Heard waiting time was long | B43: n/a | C43: =IF(ISNUMBER(B43),B43/$B$4,"n/a") -> n/a | D43: =COUNTIFS(NonAttendees!$N$2:$N$41,"Heard waiting time was long") -> 2 | E43: =IF(ISNUMBER(D43),D43/$B$5,"n/a") -> 0.05
A44: Was unwell or away | B44: n/a | C44: =IF(ISNUMBER(B44),B44/$B$4,"n/a") -> n/a | D44: =COUNTIFS(NonAttendees!$N$2:$N$41,"Was unwell or away") -> 2 | E44: =IF(ISNUMBER(D44),D44/$B$5,"n/a") -> 0.05
A45: No major barrier | B45: =COUNTIFS(Attendees!$M$2:$M$31,"No major barrier") -> 10 | C45: =IF(ISNUMBER(B45),B45/$B$4,"n/a") -> 0.33333333 | D45: n/a | E45: =IF(ISNUMBER(D45),D45/$B$5,"n/a") -> n/a
A46: Total (check: equals group size) | B46: =SUM(B35:B45) -> 30 | C46: =B46/$B$4 -> 1 | D46: =SUM(D35:D45) -> 40 | E46: =D46/$B$5 -> 1
A49: 3. Where the information gap sits, by community
...

Sheet Notes
A1: Notes and assumptions
A3: Purpose | B3: Side-by-side comparison for Daura LGA (Katsina): 30 attendees, 40 non-attender households, 3 staff records.
A4: PRACTICE DATA | B4: All data is synthetic. The attendee and staff records come from the practice dataset; the non-attender survey was generated for this demonstration. Nothing here is a real programme result, and the non-attender patterns were designed, not discovered.
A5: Denominators | B5: Attendees: 30. Non-attenders: 40. Aware non-attenders: 28. Attendee improvement asks: 29 answered. Attendee waits: 29 recorded. Distance: 29 attendee answers, 38 non-attender answers. Travel time: 30 attendee answers, 39 non-attender answers.
A6: Medians | B6: Distance and travel time use medians. One attendee reported a 295-minute journey.
A7: Like-for-like | B7: Attendees reported the main barrier before attending; non-attenders gave the main reason for not attending. The two questions differ, so groups are compared by theme, not as identical measures.
A8: Mapping: information | B8: Attendee "Lack of information" = non-attender "Did not know about it". Non-attender "Heard too late" has no attendee equivalent and is also counted as information-related.
A9: Mapping: shared groups | B9: Distance/transport cost; Work/household responsibilities; Language/communication; Previous bad service experience appear in both.
A10: Attendee only | B10: Cost of other related services; No major barrier.
A11: Non-attender only | B11: Concern about the service; Heard waiting time was long; Was unwell or away.
A12: Would use again vs would attend | B12: Different questions. Shown side by side but not equivalent.
A13: Small numbers | B13: Staff: 3 records. Communities: 15 attendees and 20 households each. Read counts, not only percentages. Avoid words such as "proves" or "caused".

Sheet Attendees
A1: Beneficiary_ID | B1: Outreach_Date | C1: Community | D1: Age_Group | E1: Sex | F1: Respondent_Type | G1: Service_Received | H1: First_Time_Receiving_Service | I1: Previous_Access_to_Service | J1: How_Heard_About_Outreach | K1: Distance_to_Outreach_Km | L1: Travel_Time_Minutes | M1: Main_Barrier_Before_Attending | N1: Preferred_Communication_Language | O1: Translator_Used | P1: Waiting_Time_Minutes | Q1: Satisfaction_Score_1_to_5 | R1: Overall_Experience | S1: Would_Use_Service_Again | T1: What_Would_Improve_Next_Outreach
A2: BEN-2026015 | B2: 2026-05-04 | C2: Kusugu | D2: Under 1 | E2: Female | F2: Parent/Guardian/Caregiver | G2: Catch-up Immunization | H2: No | I2: Health Center/Hospital | J2: Family/friend | K2: 4.2 | L2: 58 | M2: Previous bad service experience | N2: Hausa | O2: No | P2: 51 | Q2: 3 | R2: Neutral | S2: Maybe | T2: More outreach days
A3: BEN-2026022 | B3: 2026-05-12 | C3: Sarkin Yara | D3: 10–17 | E3: Male | F3: Self | G3: Catch-up Immunization | H3: Yes | I3: Never | J3: CHW | K3: 1.7 | L3: 33 | M3: No major barrier | N3: Pidgin | O3: No | P3: 58 | Q3: 3 | R3: Negative | S3: No | T3: Shorter waiting time
A4: BEN-2026036 | B4: 2026-05-19 | C4: Kusugu | D4: 1–4 | E4: Female | F4: Parent/Guardian/Caregiver | G4: Routine Immunization | H4: No | I4: Previous Outreach | J4: Health facility | K4: 8.2 | L4: 96 | M4: Lack of information | N4: Hausa | O4: No | P4: 53 | Q4: 3 | R4: Neutral | S4: Maybe | T4: Shorter waiting time
A5: BEN-2026039 | B5: 2026-05-25 | C5: Sarkin Yara | D5: Under 1 | E5: Male | F5: Parent/Guardian/Caregiver | G5: Routine Immunization | H5: Yes | I5: Never | J5: CHW | K5: 3 | L5: 295 | M5: Work/household responsibilities | N5: Hausa | O5: No | P5: 79 | Q5: 3 | R5: Neutral | S5: Maybe | T5: More outreach days
A6: BEN-2026046 | B6: 2026-05-20 | C6: Sarkin Yara | D6: Under 1 | E6: Male | F6: Parent/Guardian/Caregiver | G6: Catch-up Immunization | H6: Yes | I6: Never | J6: Health facility | K6: 5.9 | L6: 58 | M6: Distance/transport cost | N6: Hausa | O6: No | Q6: 3 | R6: Positive | S6: Yes | T6: More info before outreach
A7: BEN-2026050 | B7: 2026-05-05 | C7: Sarkin Yara | D7: 1–4 | E7: Male | F7: Parent/Guardian/Caregiver | G7: Routine Immunization | H7: Yes | I7: Never | J7: Health facility | K7: 7.4 | L7: 81 | M7: Distance/transport cost | N7: Pidgin | O7: No | P7: 73 | Q7: 3 | R7: Neutral | S7: Yes | T7: Closer service point
A8: BEN-2026061 | B8: 2026-05-27 | C8: Kusugu | D8: Under 1 | E8: Male | F8: Parent/Guardian/Caregiver | G8: Routine Immunization | H8: Yes | I8: Never | J8: Community leader | K8: 2 | L8: 33 | M8: No major barrier | N8: English | O8: No | P8: 21 | Q8: 1 | R8: Neutral | S8: Yes | T8: Closer service point
A9: BEN-2026084 | B9: 2026-05-13 | C9: Kusugu | D9: Under 1 | E9: Male | F9: Parent/Guardian/Caregiver | G9: Catch-up Immunization | H9: Yes | I9: Never | J9: CHW | L9: 17 | M9: No major barrier | N9: Hausa | O9: No | P9: 99 | Q9: 4 | R9: Very positive | S9: Yes | T9: Closer service point
A10: BEN-2026089 | B10: 2026-05-18 | C10: Sarkin Yara | D10: 1–4 | E10: Female | F10: Parent/Guardian/Caregiver | G10: Routine Immunization | H10: No | I10: Private Clinic | J10: Health facility | K10: 1.3 | L10: 28 | M10: Lack of information | N10: Hausa | O10: No | P10: 39 | Q10: 4 | R10: Neutral | S10: Yes
A11: BEN-2026107 | B11: 2026-05-13 | C11: Kusugu | D11: 1–4 | E11: Female | F11: Parent/Guardian/Caregiver | G11: Routine Immunization | H11: No | I11: Health Center/Hospital | J11: Community leader | K11: 1.1 | L11: 22 | M11: No major barrier | N11: Hausa | O11: No | P11: 53 | Q11: 2 | R11: Negative | S11: Maybe | T11: Shorter waiting time
A12: BEN-2026161 | B12: 2026-05-13 | C12: Sarkin Yara | D12: Under 1 | E12: Male | F12: Parent/Guardian/Caregiver | G12: Routine Immunization | H12: Yes | I12: Never | J12: Social media | K12: 2.5 | L12: 42 | M12: No major barrier | N12: English | O12: No | P12: 60 | Q12: 4 | R12: Very positive | S12: Yes | T12: Shorter waiting time
A13: BEN-2026197 | B13: 2026-05-13 | C13: Sarkin Yara | D13: Under 1 | E13: Female | F13: Parent/Guardian/Caregiver | G13: Catch-up Immunization | H13: No | I13: Health Center/Hospital | J13: CHW | K13: 1.3 | L13: 25 | M13: Language/communication | N13: Hausa | O13: No | P13: 48 | Q13: 5 | R13: Positive | S13: Yes | T13: More info before outreach
A14: BEN-2026198 | B14: 2026-05-11 | C14: Sarkin Yara | D14: 1–4 | E14: Male | F14: Parent/Guardian/Caregiver | G14: Catch-up Immunization | H14: No | I14: Health Center/Hospital | J14: Health facility | K14: 2.3 | L14: 25 | M14: Cost of other related services | N14: Hausa | O14: No | P14: 73 | Q14: 3 | R14: Neutral | S14: Yes | T14: No additional support
A15: BEN-2026250 | B15: 2026-05-13 | C15: Sarkin Yara | D15: Under 1 | E15: Female | F15: Parent/Guardian/Caregiver | G15: Routine Immunization | H15: No | I15: Previous Outreach | J15: Religious/community group | K15: 2.2 | L15: 34 | M15: Lack of information | N15: Hausa | O15: No | P15: 40 | Q15: 2 | R15: Negative | S15: No | T15: More info before outreach
A16: BEN-2026255 | B16: 2026-05-05 | C16: Sarkin Yara | D16: 1–4 | E16: Male | F16: Parent/Guardian/Caregiver | G16: Routine Immunization | H16: Yes | I16: Never | J16: Radio | K16: 0.9 | L16: 21 | M16: Previous bad service experience | N16: Hausa | O16: No | P16: 23 | Q16: 2 | R16: Negative | S16: Yes | T16: More info before outreach
A17: BEN-2026274 | B17: 2026-05-11 | C17: Sarkin Yara | D17: 5–9 | E17: Female | F17: Parent/Guardian/Caregiver | G17: Catch-up Immunization | H17: No | I17: Health Center/Hospital | J17: CHW | K17: 2.6 | L17: 32 | M17: No major barrier | N17: Hausa | O17: No | P17: 17 | Q17: 4 | R17: Positive | S17: Yes | T17: Shorter waiting time
A18: BEN-2026310 | B18: 2026-05-06 | C18: Kusugu | D18: 45+ | E18: Female | F18: Self | G18: COVID-19 Vaccination | H18: Yes | I18: Never | J18: CHW | K18: 0.8 | L18: 17 | M18: No major barrier | N18: Hausa | O18: No | P18: 29 | Q18: 4 | R18: Positive | S18: Yes | T18: More outreach days
A19: BEN-2026315 | B19: 2026-05-19 | C19: Sarkin Yara | D19: 5–9 | E19: Male | F19: Parent/Guardian/Caregiver | G19: HPV Vaccination | H19: No | I19: Previous Outreach | J19: CHW | K19: 0.8 | L19: 18 | M19: Language/communication | N19: Hausa | O19: Yes | P19: 76 | Q19: 3 | R19: Neutral | S19: Maybe | T19: Closer service point
A20: BEN-2026316 | B20: 2026-05-25 | C20: Sarkin Yara | D20: 1–4 | E20: Female | F20: Parent/Guardian/Caregiver | G20: Routine Immunization | H20: No | I20: Health Center/Hospital | J20: Radio | K20: 3.4 | L20: 43 | M20: Distance/transport cost | N20: Hausa | O20: No | P20: 19 | Q20: 3 | R20: Neutral | S20: Maybe | T20: More outreach days
A21: BEN-2026318 | B21: 2026-05-19 | C21: Kusugu | D21: Under 1 | E21: Male | F21: Parent/Guardian/Caregiver | G21: Routine Immunization | H21: No | I21: Health Center/Hospital | J21: Religious/community group | K21: 3.7 | L21: 60 | M21: Distance/transport cost | N21: Hausa | O21: No | P21: 43 | Q21: 2 | R21: Negative | S21: Maybe | T21: More outreach days
A22: BEN-2026321 | B22: 2026-05-13 | C22: Kusugu | D22: 5–9 | E22: Female | F22: Parent/Guardian/Caregiver | G22: Catch-up Immunization | H22: No | I22: Previous Outreach | J22: Community leader | K22: 2.4 | L22: 33 | M22: No major barrier | N22: Hausa | O22: No | P22: 48 | Q22: 3 | R22: Neutral | S22: Yes | T22: Closer service point
A23: BEN-2026342 | B23: 2026-05-18 | C23: Kusugu | D23: 25–34 | E23: Female | F23: Self | G23: COVID-19 Vaccination | H23: Yes | I23: Health Center/Hospital | J23: Radio | K23: 0.9 | L23: 22 | M23: Language/communication | N23: English | O23: No | P23: 36 | Q23: 4 | R23: Positive | S23: Yes | T23: Shorter waiting time
A24: BEN-2026363 | B24: 2026-05-11 | C24: Kusugu | D24: 5–9 | E24: Female | F24: Parent/Guardian/Caregiver | G24: Catch-up Immunization | H24: No | I24: Previous Outreach | J24: Health facility | K24: 1.6 | L24: 21 | M24: Lack of information | O24: No | P24: 28 | Q24: 5 | R24: Very positive | S24: Yes | T24: More info before outreach
A25: BEN-2026412 | B25: 2026-05-05 | C25: Kusugu | D25: Under 1 | E25: Female | F25: Parent/Guardian/Caregiver | G25: Routine Immunization | H25: No | I25: Private Clinic | J25: CHW | K25: 1 | L25: 27 | M25: Lack of information | N25: Hausa | O25: No | P25: 24 | Q25: 3 | R25: Neutral | S25: Yes | T25: Shorter waiting time
A26: BEN-2026446 | B26: 2026-05-18 | C26: Kusugu | D26: 5–9 | E26: Male | F26: Parent/Guardian/Caregiver | G26: Routine Immunization | H26: No | I26: Previous Outreach | J26: Health facility | K26: 8.2 | L26: 92 | M26: Lack of information | N26: Hausa | O26: No | P26: 76 | Q26: 3 | R26: Neutral | S26: Yes | T26: Shorter waiting time
A27: BEN-2026458 | B27: 2026-05-12 | C27: Kusugu | D27: 10–17 | E27: Male | F27: Parent/Guardian/Caregiver | G27: Catch-up Immunization | H27: No | I27: Previous Outreach | J27: CHW | K27: 4.3 | L27: 39 | M27: Work/household responsibilities | N27: Hausa | O27: No | P27: 54 | Q27: 3 | R27: Negative | S27: Maybe | T27: Shorter waiting time
A28: BEN-2026471 | B28: 2026-05-06 | C28: Sarkin Yara | D28: Under 1 | E28: Male | F28: Parent/Guardian/Caregiver | G28: Routine Immunization | H28: No | I28: Private Clinic | J28: Family/friend | K28: 0.8 | L28: 23 | M28: No major barrier | N28: English | O28: No | P28: 75 | Q28: 1 | R28: Negative | S28: Yes | T28: More outreach days
A29: BEN-2026476 | B29: 2026-05-04 | C29: Kusugu | D29: 25–34 | E29: Female | F29: Self | G29: Catch-up Immunization | H29: No | I29: Previous Outreach | J29: Community leader | K29: 4.3 | L29: 45 | M29: Lack of information | N29: Hausa | O29: Yes | P29: 41 | Q29: 4 | R29: Positive | S29: Maybe | T29: Shorter waiting time
A30: BEN-2026487 | B30: 2026-05-13 | C30: Kusugu | D30: Under 1 | E30: Female | F30: Parent/Guardian/Caregiver | G30: Routine Immunization | H30: No | I30: Health Center/Hospital | J30: CHW | K30: 3.4 | L30: 42 | M30: Language/communication | N30: Hausa | O30: No | P30: 48 | Q30: 3 | R30: Negative | S30: No | T30: Closer service point
A31: BEN-2026493 | B31: 2026-05-19 | C31: Sarkin Yara | D31: 5–9 | E31: Female | F31: Parent/Guardian/Caregiver | G31: Routine Immunization | H31: No | I31: Never | J31: CHW | K31: 2.1 | L31: 40 | M31: No major barrier | N31: Hausa | O31: No | P31: 42 | Q31: 4 | R31: Positive | S31: Yes | T31: More info before outreach

Sheet NonAttendees
A1: Household_ID | B1: Survey_Date | C1: State | D1: LGA | E1: Community | F1: Respondent_Type | G1: Respondent_Sex | H1: Person_Needing_Service_Age_Group | I1: Service_Needed | J1: Distance_to_Outreach_Km | K1: Travel_Time_Minutes | L1: Aware_of_Outreach | M1: How_Heard_About_Outreach | N1: Main_Reason_Did_Not_Attend | O1: Would_Attend_Next_Time | P1: What_Would_Help_Most | Q1: Preferred_Communication_Language | R1: Recorded_By
A2: NA-001 | B2: 2026-06-09 | C2: Katsina | D2: Daura | E2: Kusugu | F2: Parent/Guardian/Caregiver | G2: Female | H2: 1–4 | I2: Catch-up Immunization | J2: 5.4 | K2: 61 | L2: Yes | M2: Social media | N2: Distance/transport cost | O2: Yes | P2: Closer service point | Q2: Hausa | R2: CHW
A3: NA-002 | B3: 2026-06-07 | C3: Katsina | D3: Daura | E3: Kusugu | F3: Parent/Guardian/Caregiver | G3: Female | H3: 1–4 | I3: Routine Immunization | J3: 4.9 | K3: 53 | L3: Yes | M3: Community leader | N3: Work/household responsibilities | O3: Maybe | P3: More info before outreach | Q3: Hausa | R3: CHW
A4: NA-003 | B4: 2026-06-02 | C4: Katsina | D4: Daura | E4: Kusugu | F4: Parent/Guardian/Caregiver | G4: Male | H4: 1–4 | I4: Routine Immunization | J4: 9.3 | K4: 89 | L4: Yes | M4: CHW | N4: Was unwell or away | O4: Yes | P4: More info before outreach | Q4: Hausa | R4: CHW
A5: NA-004 | B5: 2026-06-04 | C5: Katsina | D5: Daura | E5: Sarkin Yara | F5: Parent/Guardian/Caregiver | G5: Female | H5: 5–9 | I5: Catch-up Immunization | J5: 1.7 | K5: 22 | L5: No | M5: Did not hear about it | N5: Did not know about it | O5: Yes | P5: Reminder call or SMS | Q5: Hausa | R5: CHW
A6: NA-005 | B6: 2026-06-09 | C6: Katsina | D6: Daura | E6: Kusugu | F6: Parent/Guardian/Caregiver | G6: Male | H6: Under 1 | I6: Routine Immunization | J6: 1.1 | K6: 20 | L6: No | M6: Did not hear about it | N6: Did not know about it | O6: No | P6: Closer service point | Q6: Hausa | R6: CHW
A7: NA-006 | B7: 2026-06-12 | C7: Katsina | D7: Daura | E7: Kusugu | F7: Parent/Guardian/Caregiver | G7: Female | H7: Under 1 | I7: Routine Immunization | J7: 5.6 | K7: 62 | L7: Yes | M7: Health facility | N7: Concern about the service | O7: Maybe | P7: More outreach days | Q7: English | R7: Volunteer
A8: NA-007 | B8: 2026-06-02 | C8: Katsina | D8: Daura | E8: Sarkin Yara | F8: Self | G8: Female | H8: 25–34 | I8: COVID-19 Vaccination | J8: 2.2 | K8: 36 | L8: Yes | M8: Radio | N8: Heard too late | O8: Yes | P8: Closer service point | Q8: Hausa | R8: CHW
A9: NA-008 | B9: 2026-06-10 | C9: Katsina | D9: Daura | E9: Sarkin Yara | F9: Parent/Guardian/Caregiver | G9: Male | H9: 5–9 | I9: Catch-up Immunization | K9: 24 | L9: Yes | M9: Community leader | N9: Work/household responsibilities | O9: Yes | P9: More privacy | Q9: Hausa | R9: CHW
A10: NA-009 | B10: 2026-06-09 | C10: Katsina | D10: Daura | E10: Sarkin Yara | F10: Self | G10: Female | H10: 45+ | I10: COVID-19 Vaccination | J10: 2.8 | K10: 43 | L10: No | M10: Did not hear about it | N10: Did not know about it | O10: Maybe | P10: More info before outreach | Q10: Hausa | R10: CHW
A11: NA-010 | B11: 2026-06-10 | C11: Katsina | D11: Daura | E11: Kusugu | F11: Parent/Guardian/Caregiver | G11: Female | H11: Under 1 | I11: Catch-up Immunization | J11: 2.4 | K11: 45 | L11: Yes | M11: CHW | N11: Distance/transport cost | O11: Yes | P11: Reminder call or SMS | Q11: Hausa | R11: CHW
A12: NA-011 | B12: 2026-06-05 | C12: Katsina | D12: Daura | E12: Sarkin Yara | F12: Parent/Guardian/Caregiver | G12: Male | H12: 1–4 | I12: Routine Immunization | J12: 4.2 | K12: 46 | L12: Yes | M12: Religious/community group | N12: Heard too late | O12: Yes | P12: More outreach days | Q12: Hausa | R12: CHW
A13: NA-012 | B13: 2026-06-02 | C13: Katsina | D13: Daura | E13: Kusugu | F13: Parent/Guardian/Caregiver | G13: Female | H13: Under 1 | I13: Routine Immunization | J13: 5.9 | K13: 61 | L13: Yes | M13: Family/friend | N13: Was unwell or away | O13: Yes | P13: More outreach days | Q13: English | R13: Volunteer
A14: NA-013 | B14: 2026-06-04 | C14: Katsina | D14: Daura | E14: Kusugu | F14: Parent/Guardian/Caregiver | G14: Female | H14: 1–4 | I14: Routine Immunization | J14: 6.6 | K14: 61 | L14: No | M14: Did not hear about it | N14: Did not know about it | O14: Yes | P14: Reminder call or SMS | Q14: Hausa | R14: Volunteer
A15: NA-014 | B15: 2026-06-12 | C15: Katsina | D15: Daura | E15: Sarkin Yara | F15: Parent/Guardian/Caregiver | G15: Female | H15: 10–17 | I15: HPV Vaccination | J15: 3.5 | K15: 48 | L15: Yes | M15: Radio | N15: Work/household responsibilities | O15: Maybe | P15: More info before outreach | Q15: Hausa | R15: Volunteer
A16: NA-015 | B16: 2026-06-12 | C16: Katsina | D16: Daura | E16: Sarkin Yara | F16: Self | G16: Female | H16: 18–24 | I16: Catch-up Immunization | J16: 2.7 | K16: 41 | L16: No | M16: Did not hear about it | N16: Did not know about it | O16: Maybe | P16: More privacy | Q16: Hausa | R16: Volunteer
A17: NA-016 | B17: 2026-06-07 | C17: Katsina | D17: Daura | E17: Kusugu | F17: Parent/Guardian/Caregiver | G17: Male | H17: Under 1 | I17: Routine Immunization | J17: 2.5 | L17: Yes | M17: Health facility | N17: Heard too late | O17: No | P17: Closer service point | Q17: Hausa | R17: CHW
A18: NA-017 | B18: 2026-06-12 | C18: Katsina | D18: Daura | E18: Kusugu | F18: Parent/Guardian/Caregiver | G18: Male | H18: 1–4 | I18: Catch-up Immunization | J18: 0.8 | K18: 22 | L18: Yes | M18: CHW | N18: Distance/transport cost | O18: Yes | P18: Home visit by health worker | Q18: Hausa | R18: CHW
A19: NA-018 | B19: 2026-06-08 | C19: Katsina | D19: Daura | E19: Sarkin Yara | F19: Parent/Guardian/Caregiver | G19: Male | H19: 1–4 | I19: Catch-up Immunization | J19: 3.9 | K19: 51 | L19: Yes | M19: Radio | N19: Distance/transport cost | O19: No | P19: Shorter waiting time | Q19: Hausa | R19: Volunteer
A20: NA-019 | B20: 2026-06-03 | C20: Katsina | D20: Daura | E20: Kusugu | F20: Parent/Guardian/Caregiver | G20: Male | H20: Under 1 | I20: Routine Immunization | J20: 4.1 | K20: 48 | L20: No | M20: Did not hear about it | N20: Did not know about it | O20: Yes | P20: Closer service point | Q20: Hausa | R20: CHW
A21: NA-020 | B21: 2026-06-01 | C21: Katsina | D21: Daura | E21: Sarkin Yara | F21: Parent/Guardian/Caregiver | G21: Male | H21: 10–17 | I21: HPV Vaccination | J21: 2.8 | K21: 40 | L21: Yes | M21: Health facility | N21: Work/household responsibilities | O21: Yes | P21: Shorter waiting time | Q21: English | R21: CHW
A22: NA-021 | B22: 2026-06-04 | C22: Katsina | D22: Daura | E22: Kusugu | F22: Parent/Guardian/Caregiver | G22: Female | H22: Under 1 | I22: Catch-up Immunization | J22: 1.7 | K22: 27 | L22: Yes | M22: Health facility | N22: Heard too late | O22: Maybe | P22: Shorter waiting time | Q22: Hausa | R22: Volunteer
A23: NA-022 | B23: 2026-06-02 | C23: Katsina | D23: Daura | E23: Kusugu | F23: Parent/Guardian/Caregiver | G23: Male | H23: Under 1 | I23: Catch-up Immunization | J23: 6.7 | K23: 63 | L23: Yes | M23: Community leader | N23: Previous bad service experience | O23: Yes | P23: Reminder call or SMS | Q23: Hausa | R23: Volunteer
A24: NA-023 | B24: 2026-06-08 | C24: Katsina | D24: Daura | E24: Kusugu | F24: Parent/Guardian/Caregiver | G24: Female | H24: Under 1 | I24: Catch-up Immunization | J24: 3.1 | K24: 44 | L24: Yes | M24: Community leader | N24: Work/household responsibilities | O24: Maybe | P24: More info before outreach | Q24: English | R24: CHW
A25: NA-024 | B25: 2026-06-04 | C25: Katsina | D25: Daura | E25: Sarkin Yara | F25: Parent/Guardian/Caregiver | G25: Male | H25: 5–9 | I25: Catch-up Immunization | K25: 26 | L25: No | M25: Did not hear about it | N25: Did not know about it | O25: Yes | P25: Reminder call or SMS | Q25: Hausa | R25: CHW
A26: NA-025 | B26: 2026-06-02 | C26: Katsina | D26: Daura | E26: Sarkin Yara | F26: Parent/Guardian/Caregiver | G26: Female | H26: 1–4 | I26: Catch-up Immunization | J26: 3.3 | K26: 44 | L26: No | M26: Did not hear about it | N26: Did not know about it | O26: Yes | P26: More outreach days | Q26: Hausa | R26: Volunteer
A27: NA-026 | B27: 2026-06-06 | C27: Katsina | D27: Daura | E27: Kusugu | F27: Parent/Guardian/Caregiver | G27: Female | H27: Under 1 | I27: Routine Immunization | J27: 2.4 | K27: 28 | L27: No | M27: Did not hear about it | N27: Did not know about it | O27: Maybe | P27: Closer service point | Q27: Hausa | R27: Volunteer
A28: NA-027 | B28: 2026-06-06 | C28: Katsina | D28: Daura | E28: Sarkin Yara | F28: Parent/Guardian/Caregiver | G28: Female | H28: 10–17 | I28: HPV Vaccination | J28: 4.2 | K28: 44 | L28: Yes | M28: CHW | N28: Distance/transport cost | O28: Maybe | P28: Closer service point | Q28: Hausa | R28: CHW
A29: NA-028 | B29: 2026-06-10 | C29: Katsina | D29: Daura | E29: Sarkin Yara | F29: Self | G29: Female | H29: 25–34 | I29: COVID-19 Vaccination | J29: 2.7 | K29: 29 | L29: Yes | M29: CHW | N29: Heard too late | O29: No | P29: Closer service point | Q29: English | R29: Volunteer
A30: NA-029 | B30: 2026-06-04 | C30: Katsina | D30: Daura | E30: Kusugu | F30: Parent/Guardian/Caregiver | G30: Male | H30: Under 1 | I30: Catch-up Immunization | J30: 3.8 | K30: 48 | L30: Yes | M30: CHW | N30: Concern about the service | O30: Yes | P30: Reminder call or SMS | Q30: Hausa | R30: CHW
A31: NA-030 | B31: 2026-06-06 | C31: Katsina | D31: Daura | E31: Sarkin Yara | F31: Self | G31: Female | H31: 18–24 | I31: COVID-19 Vaccination | J31: 3.1 | K31: 45 | L31: Yes | M31: Community leader | N31: Previous bad service experience | O31: Maybe | P31: Home visit by health worker | Q31: Hausa | R31: CHW
A32: NA-031 | B32: 2026-06-02 | C32: Katsina | D32: Daura | E32: Sarkin Yara | F32: Parent/Guardian/Caregiver | G32: Female | H32: 1–4 | I32: Routine Immunization | J32: 1.9 | K32: 30 | L32: Yes | M32: Community leader | N32: Heard waiting time was long | O32: Maybe | P32: Home visit by health worker | Q32: Pidgin | R32: CHW
A33: NA-032 | B33: 2026-06-10 | C33: Katsina | D33: Daura | E33: Sarkin Yara | F33: Parent/Guardian/Caregiver | G33: Female | H33: 10–17 | I33: HPV Vaccination | J33: 4.9 | K33: 58 | L33: No | M33: Did not hear about it | N33: Did not know about it | O33: Maybe | P33: Shorter waiting time | Q33: Hausa | R33: Volunteer
A34: NA-033 | B34: 2026-06-12 | C34: Katsina | D34: Daura | E34: Kusugu | F34: Parent/Guardian/Caregiver | G34: Male | H34: Under 1 | I34: Routine Immunization | J34: 6.7 | K34: 65 | L34: Yes | M34: CHW | N34: Previous bad service experience | O34: Maybe | P34: More info before outreach | Q34: Hausa | R34: Volunteer
A35: NA-034 | B35: 2026-06-02 | C35: Katsina | D35: Daura | E35: Sarkin Yara | F35: Parent/Guardian/Caregiver | G35: Male | H35: 1–4 | I35: Routine Immunization | J35: 6.7 | K35: 70 | L35: No | M35: Did not hear about it | N35: Did not know about it | O35: No | P35: More info before outreach | Q35: Pidgin | R35: Volunteer
A36: NA-035 | B36: 2026-06-10 | C36: Katsina | D36: Daura | E36: Kusugu | F36: Parent/Guardian/Caregiver | G36: Female | H36: 1–4 | I36: Catch-up Immunization | J36: 2.3 | K36: 25 | L36: Yes | M36: CHW | N36: Concern about the service | O36: Yes | P36: More outreach days | Q36: Hausa | R36: Volunteer
A37: NA-036 | B37: 2026-06-04 | C37: Katsina | D37: Daura | E37: Sarkin Yara | F37: Parent/Guardian/Caregiver | G37: Male | H37: 1–4 | I37: Catch-up Immunization | J37: 5.3 | K37: 53 | L37: No | M37: Did not hear about it | N37: Did not know about it | O37: Yes | P37: Home visit by health worker | Q37: Hausa | R37: CHW
... A41: NA-040 | B41: 2026-06-09 | C41: Katsina | D41: Daura | E41: Sarkin Yara | F41: Self | G41: Female | H41: 35–44 | I41: COVID-19 Vaccination | J41: 1.3 | K41: 26 | L41: Yes | M41: CHW | N41: Language/communication | O41: No | P41: Home visit by health worker | Q41: English | R41: Volunteer

Sheet Staff
A1: Staff_ID | B1: Outreach_Date | C1: Community | D1: Role | E1: Community_Mobilization_1_to_5 | F1: Main_Operational_Challenge | G1: Priority_Improvement | H1: Would_Change_Something_Next_Time
A2: STF-030 | B2: 2026-05-13 | C2: Kusugu | D2: Vaccinator | E2: 3 | F2: No major challenge | G2: More supplies | H2: No
A3: STF-034 | B3: 2026-05-13 | C3: Kusugu | D3: Community Mobilizer | E3: 2 | F3: Transport/logistics | G3: Earlier community mobilization | H3: No
A4: STF-035 | B4: 2026-05-13 | C4: Kusugu | D4: CHW | E4: 1 | F4: Transport/logistics | G4: More supplies | H4: Yes
